<?xml version="1.0" ?>
<!-- =================================================================================== -->
<!-- |    This document was autogenerated by xacro from origin.urdf.xacro              | -->
<!-- |    EDITING THIS FILE BY HAND IS NOT RECOMMENDED                                 | -->
<!-- =================================================================================== -->
<robot name="origin">
  <material name="silver">
    <color rgba="0.700 0.700 0.700 1.000"/>
  </material>
  <material name="grey">
    <color rgba="0.5 0.5 0.5 1.000"/>
  </material>
  <material name="matte_black">
    <color rgba="0.1568 0.1568 0.1686 1.000"/>
  </material>
  <material name="shiny_white">
    <color rgba="1.0 1.0 1.0 1.0"/>
  </material>
  <link name="rviz_world"/>
  <joint name="right_shoulder_y" type="revolute">
    <origin rpy="0 0 0" xyz="0.0001 -0.1099 1.0243"/>
    <parent link="rviz_world"/>
    <child link="right_shoulder_link"/>
    <axis xyz="0.0 -1.0 0.0"/>
    <limit effort="27" lower="-3.141592653589793" upper="3.141592653589793" velocity="0.3"/>
  </joint>
  <link name="right_shoulder_link">
    <inertial>
      <origin rpy="0 0 0" xyz="-6.707197303895294e-05 -0.028863587907437732 6.661338147750939e-16"/>
      <mass value="0.5113716800487312"/>
      <inertia ixx="0.000704" ixy="-1e-06" ixz="-0.0" iyy="0.000542" iyz="-0.0" izz="0.001084"/>
    </inertial>
    <visual>
      <origin rpy="0 0 0" xyz="-0.0001 0.1099 -1.0243"/>
      <geometry>
        <mesh filename="package://origin_description/meshes/right_shoulder_link.stl" scale="0.001 0.001 0.001"/>
      </geometry>
      <material name="matte_black"/>
    </visual>
    <collision>
      <origin rpy="0 0 0" xyz="-0.0001 0.1099 -1.0243"/>
      <geometry>
        <mesh filename="package://origin_description/meshes/right_shoulder_link.stl" scale="0.001 0.001 0.001"/>
      </geometry>
    </collision>
  </link>
  <joint name="right_shoulder_x" type="revolute">
    <origin rpy="0 0 0" xyz="-0.0001 -0.0857 0.0"/>
    <parent link="right_shoulder_link"/>
    <child link="right_upper_arm_link"/>
    <limit effort="27" lower="0" upper="3.141592653589793" velocity="0.3"/>
    <axis xyz="-1.0 0.0 0.0"/>
  </joint>
  <link name="right_upper_arm_link">
    <inertial>
      <origin rpy="0 0 0" xyz="-0.00042720383197012465 -5.765147387259972e-09 -0.10194978394457499"/>
      <mass value="1.6884377602103624"/>
      <inertia ixx="0.009792" ixy="0.0" ixz="0.000221" iyy="0.010143" iyz="-0.0" izz="0.003468"/>
    </inertial>
    <visual>
      <origin rpy="0 0 0" xyz="0.0 0.1956 -1.0243"/>
      <geometry>
        <mesh filename="package://origin_description/meshes/right_upper_arm_link.stl" scale="0.001 0.001 0.001"/>
      </geometry>
      <material name="shiny_white"/>
    </visual>
    <collision>
      <origin rpy="0 0 0" xyz="0.0 0.1956 -1.0243"/>
      <geometry>
        <mesh filename="package://origin_description/meshes/right_upper_arm_link.stl" scale="0.001 0.001 0.001"/>
      </geometry>
    </collision>
  </link>
  <joint name="right_elbow_z" type="revolute">
    <origin rpy="0 0 0" xyz="-0.0001 0.0 -0.22392"/>
    <parent link="right_upper_arm_link"/>
    <child link="right_elbow_link"/>
    <limit effort="3" lower="-3.141592653589793" upper="3.141592653589793" velocity="1"/>
    <axis xyz="0.0 0.0 -1.0"/>
  </joint>
  <link name="right_elbow_link">
    <inertial>
      <origin rpy="0 0 0" xyz="0.0024366910375512828 -6.356026815979021e-15 -0.02403825817806282"/>
      <mass value="0.21096961211666773"/>
      <inertia ixx="0.000256" ixy="-0.0" ixz="1.4e-05" iyy="0.000104" iyz="0.0" izz="0.000224"/>
    </inertial>
    <visual>
      <origin rpy="0 0 0" xyz="0.0001 0.1956 -0.80038"/>
      <geometry>
        <mesh filename="package://origin_description/meshes/right_elbow_link.stl" scale="0.001 0.001 0.001"/>
      </geometry>
      <material name="shiny_white"/>
    </visual>
    <collision>
      <origin rpy="0 0 0" xyz="0.0001 0.1956 -0.80038"/>
      <geometry>
        <mesh filename="package://origin_description/meshes/right_elbow_link.stl" scale="0.001 0.001 0.001"/>
      </geometry>
    </collision>
  </link>
  <joint name="right_elbow_y" type="revolute">
    <origin rpy="0 0 0" xyz="0.030255 0.0 -0.056208"/>
    <parent link="right_elbow_link"/>
    <child link="right_forearm_link"/>
    <limit effort="3" lower="0" upper="2.0943951023931953" velocity="1"/>
    <axis xyz="0.0 -1.0 0.0"/>
  </joint>
  <link name="right_forearm_link">
    <inertial>
      <origin rpy="0 0 0" xyz="-0.011927462307960417 8.326672684688674e-17 -0.052718743037229676"/>
      <mass value="0.38687937067589206"/>
      <inertia ixx="0.001214" ixy="0.0" ixz="0.000107" iyy="0.001304" iyz="0.0" izz="0.000553"/>
    </inertial>
    <visual>
      <origin rpy="0 0 0" xyz="-0.030155 0.1956 -0.744172"/>
      <geometry>
        <mesh filename="package://origin_description/meshes/right_forearm_link.stl" scale="0.001 0.001 0.001"/>
      </geometry>
      <material name="matte_black"/>
    </visual>
    <collision>
      <origin rpy="0 0 0" xyz="-0.030155 0.1956 -0.744172"/>
      <geometry>
        <mesh filename="package://origin_description/meshes/right_forearm_link.stl" scale="0.001 0.001 0.001"/>
      </geometry>
    </collision>
  </link>
  <joint name="right_wrist_z" type="revolute">
    <origin rpy="0 0 0" xyz="0.0 -2e-05 -0.149472"/>
    <parent link="right_forearm_link"/>
    <child link="right_wrist_link"/>
    <limit effort="3" lower="-3.141592653589793" upper="3.141592653589793" velocity="1"/>
    <axis xyz="0.0 0.0 1.0"/>
  </joint>
  <link name="right_wrist_link">
    <inertial>
      <origin rpy="0 0 0" xyz="0.0002089247538572328 1.942890293094024e-15 -0.01200318430716818"/>
      <mass value="0.04301003425285144"/>
      <inertia ixx="2.3e-05" ixy="0.0" ixz="0.0" iyy="1.4e-05" iyz="0.0" izz="2e-05"/>
    </inertial>
    <visual>
      <origin rpy="0 0 0" xyz="-0.030155 0.19562 -0.5947"/>
      <geometry>
        <mesh filename="package://origin_description/meshes/right_wrist_link.stl" scale="0.001 0.001 0.001"/>
      </geometry>
      <material name="shiny_white"/>
    </visual>
    <collision>
      <origin rpy="0 0 0" xyz="-0.030155 0.19562 -0.5947"/>
      <geometry>
        <mesh filename="package://origin_description/meshes/right_wrist_link.stl" scale="0.001 0.001 0.001"/>
      </geometry>
    </collision>
  </link>
  <joint name="right_wrist_y" type="revolute">
    <origin rpy="0 0 0" xyz="0.0 0.0 -0.039"/>
    <parent link="right_wrist_link"/>
    <child link="right_hand_link"/>
    <limit effort="3" lower="-1.5707963267948966" upper="1.5707963267948966" velocity="1"/>
    <axis xyz="0.0 -1.0 0.0"/>
  </joint>
  <link name="right_hand_link">
    <inertial>
      <origin rpy="0 0 0" xyz="-0.01104767351317323 0.002715369411830093 -0.05225403748482538"/>
      <mass value="0.18001679014798885"/>
      <inertia ixx="0.000181" ixy="1.7e-05" ixz="-2.6e-05" iyy="0.000251" iyz="8e-06" izz="0.000164"/>
    </inertial>
    <visual>
      <origin rpy="0 0 0" xyz="-0.030155 0.19562 -0.5557"/>
      <geometry>
        <mesh filename="package://origin_description/meshes/right_hand_link.stl" scale="0.001 0.001 0.001"/>
      </geometry>
      <material name="shiny_white"/>
    </visual>
    <collision>
      <origin rpy="0 0 0" xyz="-0.030155 0.19562 -0.5557"/>
      <geometry>
        <mesh filename="package://origin_description/meshes/right_hand_link.stl" scale="0.001 0.001 0.001"/>
      </geometry>
    </collision>
  </link>
</robot>
