<?xml version="1.0" ?>
<robot xmlns:xacro="http://www.ros.org/wiki/xacro">
  <xacro:macro name="origin_right_arm" params="parent">
    <joint name="right_shoulder_y" type="revolute">
      <origin xyz="0.0001 -0.1099 1.0243" rpy="0 0 0"/>
      <parent link="${parent}"/>
      <child link="right_shoulder_link"/>
      <axis xyz="0.0 -1.0 0.0"/>
      <limit effort="27" velocity="0.3" lower="${-PI}" upper="${PI}" />
    </joint>

    <link name="right_shoulder_link">
      <inertial>
        <origin xyz="-6.707197303895294e-05 -0.028863587907437732 6.661338147750939e-16" rpy="0 0 0"/>
        <mass value="0.5113716800487312"/>
        <inertia ixx="0.000704" iyy="0.000542" izz="0.001084" ixy="-1e-06" iyz="-0.0" ixz="-0.0"/>
      </inertial>
      <visual>
        <origin xyz="-0.0001 0.1099 -1.0243" rpy="0 0 0"/>
        <geometry>
          <mesh filename="package://origin_hardware/description/meshes/right_shoulder_link.stl" scale="0.001 0.001 0.001"/>
        </geometry>
        <material name="matte_black"/>
      </visual>
      <collision>
        <origin xyz="-0.0001 0.1099 -1.0243" rpy="0 0 0"/>
        <geometry>
          <mesh filename="package://origin_hardware/description/meshes/right_shoulder_link.stl" scale="0.001 0.001 0.001"/>
        </geometry>
      </collision>
    </link>

    <joint name="right_shoulder_x" type="revolute">
      <origin xyz="-0.0001 -0.0857 0.0" rpy="0 0 0"/>
      <parent link="right_shoulder_link"/>
      <child link="right_upper_arm_link"/>
      <limit effort="27" velocity="0.3" lower="0" upper="${2*PI/3}" />
      <axis xyz="-1.0 0.0 0.0"/>
    </joint>

    <link name="right_upper_arm_link">
      <inertial>
        <origin xyz="-0.00042720383197012465 -5.765147387259972e-09 -0.10194978394457499" rpy="0 0 0"/>
        <mass value="1.6884377602103624"/>
        <inertia ixx="0.009792" iyy="0.010143" izz="0.003468" ixy="0.0" iyz="-0.0" ixz="0.000221"/>
      </inertial>
      <visual>
        <origin xyz="0.0 0.1956 -1.0243" rpy="0 0 0"/>
        <geometry>
          <mesh filename="package://origin_hardware/description/meshes/right_upper_arm_link.stl" scale="0.001 0.001 0.001"/>
        </geometry>
        <material name="shiny_white"/>
      </visual>
      <collision>
        <origin xyz="0.0 0.1956 -1.0243" rpy="0 0 0"/>
        <geometry>
          <mesh filename="package://origin_hardware/description/meshes/right_upper_arm_link.stl" scale="0.001 0.001 0.001"/>
        </geometry>
      </collision>
    </link>

    <joint name="right_elbow_z" type="revolute">
      <origin xyz="-0.0001 0.0 -0.22392" rpy="0 0 0"/>
      <parent link="right_upper_arm_link"/>
      <child link="right_elbow_link"/>
      <limit effort="3" velocity="1" lower="${-PI}" upper="${PI}" />
      <axis xyz="0.0 0.0 -1.0"/>
    </joint>

    <link name="right_elbow_link">
      <inertial>
        <origin xyz="0.0024366910375512828 -6.356026815979021e-15 -0.02403825817806282" rpy="0 0 0"/>
        <mass value="0.21096961211666773"/>
        <inertia ixx="0.000256" iyy="0.000104" izz="0.000224" ixy="-0.0" iyz="0.0" ixz="1.4e-05"/>
      </inertial>
      <visual>
        <origin xyz="0.0001 0.1956 -0.80038" rpy="0 0 0"/>
        <geometry>
          <mesh filename="package://origin_hardware/description/meshes/right_elbow_link.stl" scale="0.001 0.001 0.001"/>
        </geometry>
        <material name="shiny_white"/>
      </visual>
      <collision>
        <origin xyz="0.0001 0.1956 -0.80038" rpy="0 0 0"/>
        <geometry>
          <mesh filename="package://origin_hardware/description/meshes/right_elbow_link.stl" scale="0.001 0.001 0.001"/>
        </geometry>
      </collision>
    </link>

    <joint name="right_elbow_y" type="revolute">
      <origin xyz="0.030255 0.0 -0.056208" rpy="0 0 0"/>
      <parent link="right_elbow_link"/>
      <child link="right_forearm_link"/>
      <limit effort="3" velocity="1" lower="0" upper="${2*PI/3}" />
      <axis xyz="0.0 -1.0 0.0"/>
    </joint>

    <link name="right_forearm_link">
      <inertial>
        <origin xyz="-0.011927462307960417 8.326672684688674e-17 -0.052718743037229676" rpy="0 0 0"/>
        <mass value="0.38687937067589206"/>
        <inertia ixx="0.001214" iyy="0.001304" izz="0.000553" ixy="0.0" iyz="0.0" ixz="0.000107"/>
      </inertial>
      <visual>
        <origin xyz="-0.030155 0.1956 -0.744172" rpy="0 0 0"/>
        <geometry>
          <mesh filename="package://origin_hardware/description/meshes/right_forearm_link.stl" scale="0.001 0.001 0.001"/>
        </geometry>
        <material name="matte_black"/>
      </visual>
      <collision>
        <origin xyz="-0.030155 0.1956 -0.744172" rpy="0 0 0"/>
        <geometry>
          <mesh filename="package://origin_hardware/description/meshes/right_forearm_link.stl" scale="0.001 0.001 0.001"/>
        </geometry>
      </collision>
    </link>

    <joint name="right_wrist_z" type="revolute">
      <origin xyz="0.0 -2e-05 -0.149472" rpy="0 0 0"/>
      <parent link="right_forearm_link"/>
      <child link="right_wrist_link"/>
      <limit effort="3" velocity="1" lower="${-PI}" upper="${PI}" />
      <axis xyz="0.0 0.0 1.0"/>
    </joint>

    <link name="right_wrist_link">
      <inertial>
        <origin xyz="0.0002089247538572328 1.942890293094024e-15 -0.01200318430716818" rpy="0 0 0"/>
        <mass value="0.04301003425285144"/>
        <inertia ixx="2.3e-05" iyy="1.4e-05" izz="2e-05" ixy="0.0" iyz="0.0" ixz="0.0"/>
      </inertial>
      <visual>
        <origin xyz="-0.030155 0.19562 -0.5947" rpy="0 0 0"/>
        <geometry>
          <mesh filename="package://origin_hardware/description/meshes/right_wrist_link.stl" scale="0.001 0.001 0.001"/>
        </geometry>
        <material name="shiny_white"/>
      </visual>
      <collision>
        <origin xyz="-0.030155 0.19562 -0.5947" rpy="0 0 0"/>
        <geometry>
          <mesh filename="package://origin_hardware/description/meshes/right_wrist_link.stl" scale="0.001 0.001 0.001"/>
        </geometry>
      </collision>
    </link>
    
    <joint name="right_wrist_y" type="revolute">
      <origin xyz="0.0 0.0 -0.039" rpy="0 0 0"/>
      <parent link="right_wrist_link"/>
      <child link="right_hand_link"/>
      <limit effort="3" velocity="1" lower="${-PI/2}" upper="${PI/2}" />
      <axis xyz="0.0 -1.0 0.0"/>
    </joint>

    <link name="right_hand_link">
      <inertial>
        <origin xyz="-0.01104767351317323 0.002715369411830093 -0.05225403748482538" rpy="0 0 0"/>
        <mass value="0.18001679014798885"/>
        <inertia ixx="0.000181" iyy="0.000251" izz="0.000164" ixy="1.7e-05" iyz="8e-06" ixz="-2.6e-05"/>
      </inertial>
      <visual>
        <origin xyz="-0.030155 0.19562 -0.5557" rpy="0 0 0"/>
        <geometry>
          <mesh filename="package://origin_hardware/description/meshes/right_hand_link.stl" scale="0.001 0.001 0.001"/>
        </geometry>
        <material name="shiny_white"/>
      </visual>
      <collision>
        <origin xyz="-0.030155 0.19562 -0.5557" rpy="0 0 0"/>
        <geometry>
          <mesh filename="package://origin_hardware/description/meshes/right_hand_link.stl" scale="0.001 0.001 0.001"/>
        </geometry>
      </collision>
    </link>
    <!-- <xacro:right_gripper parent="right_hand_link"/> -->
  </xacro:macro>
</robot>
